DEBUG:boto:Retrieving credentials from metadata server.
ERROR:boto:Caught exception reading instance data
Traceback (most recent call last):
  File "/usr/lib/python2.7/site-packages/boto/utils.py", line 210, in retry_url
    r = opener.open(req, timeout=timeout)
  File "/usr/lib/python2.7/urllib2.py", line 429, in open
    response = self._open(req, data)
  File "/usr/lib/python2.7/urllib2.py", line 447, in _open
    '_open', req)
  File "/usr/lib/python2.7/urllib2.py", line 407, in _call_chain
    result = func(*args)
  File "/usr/lib/python2.7/urllib2.py", line 1228, in http_open
    return self.do_open(httplib.HTTPConnection, req)
  File "/usr/lib/python2.7/urllib2.py", line 1198, in do_open
    raise URLError(err)
URLError: <urlopen error timed out>
ERROR:boto:Unable to read instance data, giving up
